Workbook

Sheet Lisez-moi
B2: Export CRM - Orvane Solutions (données de démonstration)
B3: Jeu de données pivot commun aux démonstrateurs « Préparation des visites commerciales » (Claude, Gemini, Copilot).
B5: Contexte
B6: Société | C6: Orvane Solutions, société fictive : fabricant français de solutions d'emballage (étuis, étiquettes, coffrets, caisses) et d'équipements de conditionnement.
B7: Format | C7: Export simulé d'un CRM de type HubSpot ou Salesforce : un onglet par objet, une ligne d'en-tête, des identifiants stables reliant les onglets.
B8: Date de l'export | C8: =DateExport
B9: Historique | C9: Activités depuis janvier 2025, commandes depuis octobre 2024, rendez-vous planifiés jusqu'à mi-novembre 2026.
B11: Avertissement
B12: Entreprises réelles | C12: Les 30 entreprises clientes sont réelles. Leurs données publiques (adresse, site web, activité, tranche de chiffre d'affaires, groupe, code bourse) sont issues de sources publiques et vérifiées en octobre 2026, pour que l'agent puisse les enrichir avec leur actualité et leur cours de bourse.
B13: Données fictives | C13: Le fournisseur Orvane Solutions, les contacts, les échanges, les montants, les commandes, les tickets et les rendez-vous sont entièrement inventés : aucune ligne ne reflète une relation commerciale existante.
B14: Coordonnées | C14: Les e-mails utilisent le domaine réservé .example et ne peuvent pas être délivrés. Les numéros de téléphone sont fictifs.
B16: Modèle de données
B17: Onglet | C17: Contenu | D17: Lignes | E17: Clé et liens
B18: Commerciaux | C18: Équipe commerciale (propriétaires des comptes) et indicateurs de portefeuille. | D18: =COUNTA(Commerciaux!$A$2:$A$3000) | E18: ID commercial (U...)
B19: Entreprises | C19: Comptes clients, opportunités et prospects, avec contexte et enjeux. | D19: =COUNTA(Entreprises!$A$2:$A$3000) | E19: ID entreprise (E...) ; ID propriétaire → Commerciaux
B20: Contacts | C20: Interlocuteurs chez les comptes (50 contacts). | D20: =COUNTA(Contacts!$A$2:$A$3000) | E20: ID contact (C...) ; ID entreprise → Entreprises
B21: Transactions | C21: Opportunités ouvertes, gagnées et perdues du pipeline « Ventes terrain ». | D21: =COUNTA(Transactions!$A$2:$A$3000) | E21: ID transaction (T...) ; → Entreprises, Contacts, Produits
B22: Activités | C22: Historique des visites, appels, e-mails, visios et notes, avec comptes rendus. | D22: =COUNTA(Activités!$A$2:$A$3000) | E22: ID activité (A...) ; → Entreprises, Contacts, Transactions
B23: Rendez-vous | C23: Rendez-vous à venir, avec colonnes à compléter par l'assistant. | D23: =COUNTA('Rendez-vous'!$A$2:$A$3000) | E23: ID rendez-vous (R...) ; → Entreprises, Contacts, Transactions
B24: Tickets | C24: Demandes et réclamations du service client. | D24: =COUNTA(Tickets!$A$2:$A$3000) | E24: ID ticket (K...) ; → Entreprises, Contacts
B25: Commandes | C25: Historique des commandes et des livraisons. | D25: =COUNTA(Commandes!$A$2:$A$3000) | E25: ID commande (CMD-...) ; → Entreprises, Produits
B26: Produits | C26: Catalogue et prix de vente. | D26: =COUNTA(Produits!$A$2:$A$3000) | E26: ID produit (P...)
B27: Paramètres | C27: Date de l'export et listes de valeurs (phases, statuts, types). | E27: Champ nommé DateExport
B29: Lecture des en-têtes
B30: Bleu foncé | C30: Donnée saisie dans le CRM.
B31: Gris | C31: Colonne calculée par formule (ne pas saisir).
B32: Orange | C32: Colonne à compléter par l'assistant (brief préparé, compte rendu).
B34: Scénario de démonstration
B35: Commercial | C35: Julien Morel (U002), commercial terrain Hauts-de-France et Île-de-France.
B36: Lundi 12/10/2026 | C36: Trois rendez-vous : R001 Bonduelle (9h30, sur site), R002 Lesaffre (14h00, sur site), R003 Guerbet (17h00, visio).
B37: Après la visite | C37: Le compte rendu validé par le commercial peut être saisi dans Rendez-vous (colonne Compte rendu de visite) et ajouté comme nouvelle ligne de type « Visite terrain » dans Activités.

Sheet Paramètres
A1: Paramètres et listes de référence
A3: Date de l'export | B3: 46304 | C3: Date de référence de toutes les formules (champ nommé DateExport). La modifier recalcule les indicateurs.
A6: Phase de la transaction | B6: Probabilité | C6: Statut | E6: Secteur d'activité | F6: Segment | G6: Phase du cycle de vie | H6: Statut du compte | I6: Type d'activité | J6: Résultat | K6: Type de rendez-vous | L6: Statut du rendez-vous | M6: Catégorie de ticket | N6: Priorité | O6: Statut du ticket | P6: Statut de commande | Q6: Type de transaction | R6: Niveau de décision | S6: Canal préféré | T6: Source d'origine | U6: Statut du lead | V6: Oui / Non | W6: Famille de produit | X6: Tranche d'effectif | Y6: Civilité | Z6: Tranche de CA
A7: Rendez-vous programmé | B7: 0.2 | C7: Ouverte | E7: Pharmaceutique et santé | F7: Grand compte | G7: Lead | H7: Nouveau | I7: Visite terrain | J7: Positif | K7: Visite sur site | L7: Planifié | M7: Livraison | N7: Basse | O7: Nouveau | P7: En cours de livraison | Q7: Nouvelle affaire | R7: Décideur | S7: Visite | T7: Salon professionnel | U7: Nouveau | V7: Oui | W7: Consommables | X7: 1 - 49 | Y7: M. | Z7: Moins de 10 M€
A8: Qualifié pour achat | B8: 0.4 | C8: Ouverte | E8: Vins et spiritueux | F8: ETI | G8: Prospect | H8: En développement | I8: Appel | J8: Neutre | K8: Visio | L8: Confirmé | M8: Qualité produit | N8: Normale | O8: En cours | P8: Livrée | Q8: Affaire existante | R8: Influenceur | S8: Téléphone | T8: Recommandation | U8: Ouvert | V8: Non | W8: Équipements | X8: 50 - 249 | Y8: Mme | Z8: 10 - 100 M€
A9: Présentation planifiée | B9: 0.6 | C9: Ouverte | E9: Grande consommation | F9: PME | G9: Opportunité | H9: Actif | I9: E-mail | J9: À relancer | K9: Déjeuner d'affaires | L9: À reprogrammer | M9: Facturation | N9: Haute | O9: En attente client | P9: Facturée | Q9: Renouvellement | R9: Prescripteur | S9: E-mail | T9: Prospection terrain | U9: Tentative de contact | W9: Services | X9: 250 - 999 | Z9: 100 M€ - 1 Md€
A10: Décideur impliqué | B10: 0.8 | C10: Ouverte | E10: Équipements et matériaux | G10: Client | H10: À surveiller | I10: Réunion visio | J10: Négatif | L10: Annulé | M10: Technique équipement | N10: Critique | O10: Fermé | R10: Utilisateur | S10: Visio | T10: Prospection téléphonique | U10: Connecté | X10: 1 000 - 4 999 | Z10: 1 - 10 Md€
A11: Contrat envoyé | B11: 0.9 | C11: Ouverte | H11: À risque | I11: Note | L11: Réalisé | M11: Documentation | T11: Site web | U11: Affaire ouverte | X11: 5 000 - 9 999 | Z11: Plus de 10 Md€
A12: Conclu gagné | B12: 1 | C12: Gagnée | T12: Événement / webinaire | U12: Non qualifié | X12: 10 000 et plus | Z12: Non publié
A13: Conclu perdu | B13: 0 | C13: Perdue | Z13: Non publié (filiale)

Sheet Commerciaux
A1: ID commercial | B1: Prénom | C1: Nom | D1: Nom complet | E1: E-mail | F1: Téléphone mobile | G1: Profil métier | H1: Équipe | I1: Territoire | J1: Manager | K1: Date d'arrivée | L1: Objectif CA annuel (€) | M1: Comptes en portefeuille | N1: CA 12 derniers mois du portefeuille (€) | O1: Pipeline pondéré ouvert (€) | P1: Rendez-vous à venir
A2: U001 | B2: Camille | C2: Laurent | D2: =B2&" "&C2 | E2: camille.laurent@orvane-solutions.example | F2: +33 6 39 98 10 20 | G2: Directrice commerciale | H2: Direction commerciale | I2: France | K2: 43528 | M2: =COUNTIF(Entreprises!$S$2:$S$3000,A2) | N2: =SUMIFS(Entreprises!$AA$2:$AA$3000,Entreprises!$S$2:$S$3000,A2) | O2: =SUMIFS(Transactions!$M$2:$M$3000,Transactions!$G$2:$G$3000,A2,Transactions!$N$2:$N$3000,"Ouverte") | P2: =COUNTIFS('Rendez-vous'!$K$2:$K$3000,A2,'Rendez-vous'!$B$2:$B$3000,">="&DateExport)
A3: U002 | B3: Julien | C3: Morel | D3: =B3&" "&C3 | E3: julien.morel@orvane-solutions.example | F3: +33 6 39 98 17 31 | G3: Commercial terrain | H3: Ventes terrain | I3: Hauts-de-France et Île-de-France | J3: Camille Laurent | K3: 44440 | L3: 1400000 | M3: =COUNTIF(Entreprises!$S$2:$S$3000,A3) | N3: =SUMIFS(Entreprises!$AA$2:$AA$3000,Entreprises!$S$2:$S$3000,A3) | O3: =SUMIFS(Transactions!$M$2:$M$3000,Transactions!$G$2:$G$3000,A3,Transactions!$N$2:$N$3000,"Ouverte") | P3: =COUNTIFS('Rendez-vous'!$K$2:$K$3000,A3,'Rendez-vous'!$B$2:$B$3000,">="&DateExport)
A4: U003 | B4: Sarah | C4: Benali | D4: =B4&" "&C4 | E4: sarah.benali@orvane-solutions.example | F4: +33 6 39 98 24 42 | G4: Commerciale terrain | H4: Ventes terrain | I4: Champagne et Grand Est | J4: Camille Laurent | K4: 44571 | L4: 1100000 | M4: =COUNTIF(Entreprises!$S$2:$S$3000,A4) | N4: =SUMIFS(Entreprises!$AA$2:$AA$3000,Entreprises!$S$2:$S$3000,A4) | O4: =SUMIFS(Transactions!$M$2:$M$3000,Transactions!$G$2:$G$3000,A4,Transactions!$N$2:$N$3000,"Ouverte") | P4: =COUNTIFS('Rendez-vous'!$K$2:$K$3000,A4,'Rendez-vous'!$B$2:$B$3000,">="&DateExport)
A5: U004 | B5: Maxime | C5: Garnier | D5: =B5&" "&C5 | E5: maxime.garnier@orvane-solutions.example | F5: +33 6 39 98 31 53 | G5: Commercial terrain | H5: Ventes terrain | I5: Auvergne-Rhône-Alpes et Sud-Est | J5: Camille Laurent | K5: 43969 | L5: 1300000 | M5: =COUNTIF(Entreprises!$S$2:$S$3000,A5) | N5: =SUMIFS(Entreprises!$AA$2:$AA$3000,Entreprises!$S$2:$S$3000,A5) | O5: =SUMIFS(Transactions!$M$2:$M$3000,Transactions!$G$2:$G$3000,A5,Transactions!$N$2:$N$3000,"Ouverte") | P5: =COUNTIFS('Rendez-vous'!$K$2:$K$3000,A5,'Rendez-vous'!$B$2:$B$3000,">="&DateExport)
A6: U005 | B6: Élodie | C6: Fabre | D6: =B6&" "&C6 | E6: elodie.fabre@orvane-solutions.example | F6: +33 6 39 98 38 64 | G6: Commerciale terrain | H6: Ventes terrain | I6: Nouvelle-Aquitaine et Occitanie | J6: Camille Laurent | K6: 44963 | L6: 1000000 | M6: =COUNTIF(Entreprises!$S$2:$S$3000,A6) | N6: =SUMIFS(Entreprises!$AA$2:$AA$3000,Entreprises!$S$2:$S$3000,A6) | O6: =SUMIFS(Transactions!$M$2:$M$3000,Transactions!$G$2:$G$3000,A6,Transactions!$N$2:$N$3000,"Ouverte") | P6: =COUNTIFS('Rendez-vous'!$K$2:$K$3000,A6,'Rendez-vous'!$B$2:$B$3000,">="&DateExport)
A7: U006 | B7: Thomas | C7: Roussel | D7: =B7&" "&C7 | E7: thomas.roussel@orvane-solutions.example | F7: +33 6 39 98 45 75 | G7: Key Account Manager | H7: Grands comptes | I7: National - Santé | J7: Camille Laurent | K7: 43409 | L7: 2500000 | M7: =COUNTIF(Entreprises!$S$2:$S$3000,A7) | N7: =SUMIFS(Entreprises!$AA$2:$AA$3000,Entreprises!$S$2:$S$3000,A7) | O7: =SUMIFS(Transactions!$M$2:$M$3000,Transactions!$G$2:$G$3000,A7,Transactions!$N$2:$N$3000,"Ouverte") | P7: =COUNTIFS('Rendez-vous'!$K$2:$K$3000,A7,'Rendez-vous'!$B$2:$B$3000,">="&DateExport)
A8: U007 | B8: Inès | C8: Caron | D8: =B8&" "&C8 | E8: ines.caron@orvane-solutions.example | F8: +33 6 39 98 52 86 | G8: Key Account Manager | H8: Grands comptes | I8: National - Grande consommation et Industrie | J8: Camille Laurent | K8: 43633 | L8: 2800000 | M8: =COUNTIF(Entreprises!$S$2:$S$3000,A8) | N8: =SUMIFS(Entreprises!$AA$2:$AA$3000,Entreprises!$S$2:$S$3000,A8) | O8: =SUMIFS(Transactions!$M$2:$M$3000,Transactions!$G$2:$G$3000,A8,Transactions!$N$2:$N$3000,"Ouverte") | P8: =COUNTIFS('Rendez-vous'!$K$2:$K$3000,A8,'Rendez-vous'!$B$2:$B$3000,">="&DateExport)

Sheet Produits
A1: ID produit | B1: Référence | C1: Nom du produit | D1: Famille | E1: Description | F1: Unité de vente | G1: Prix unitaire HT (€) | H1: Marchés cibles | I1: Actif
A2: P001 | B2: ETU-PH-100 | C2: Étuis carton pharmaceutiques imprimés | D2: Consommables | E2: Étuis pliants en carton compact, impression offset, compatibles encartonneuses pharmaceutiques. | F2: Lot de 1 000 étuis | G2: 185 | H2: Pharmaceutique et santé | I2: Oui
A3: P002 | B3: NOT-PH-200 | C3: Notices pharmaceutiques pliées | D3: Consommables | E3: Notices papier bible pliées, multilingues, conformes aux exigences réglementaires. | F3: Lot de 1 000 notices | G3: 95 | H3: Pharmaceutique et santé | I3: Oui
A4: P003 | B4: ETQ-HR-300 | C4: Étiquettes adhésives haute définition | D4: Consommables | E4: Étiquettes papier ou synthétiques, impression numérique, résistance humidité et froid. | F4: Rouleau de 5 000 étiquettes | G4: 240 | H4: Tous marchés | I4: Oui
A5: P004 | B5: ETQ-TE-310 | C5: Étiquettes d'inviolabilité | D5: Consommables | E5: Étiquettes de première ouverture (tamper-evident) avec découpe de sécurité. | F5: Rouleau de 5 000 étiquettes | G5: 310 | H5: Pharmaceutique et santé ; Vins et spiritueux | I5: Oui
A6: P005 | B6: COF-PR-400 | C6: Coffrets rigides premium | D6: Consommables | E6: Coffrets carton rigide habillés, calage carton, finitions dorure et gaufrage. | F6: Lot de 100 coffrets | G6: 1450 | H6: Vins et spiritueux ; Grande consommation | I6: Oui
A7: P006 | B7: ETU-SP-410 | C7: Étuis spiritueux luxe | D7: Consommables | E7: Étuis carton luxe avec dorure à chaud et vernis sélectif. | F7: Lot de 500 étuis | G7: 1150 | H7: Vins et spiritueux | I7: Oui
A8: P007 | B8: CAI-OND-500 | C8: Caisses carton ondulé personnalisées | D8: Consommables | E8: Caisses américaines et wrap-around, impression flexo, cannelures adaptées au transport. | F8: Palette de 500 caisses | G8: 620 | H8: Tous marchés | I8: Oui
A9: P008 | B9: ECO-MM-520 | C9: Emballages éco-conçus mono-matériau | D9: Consommables | E9: Étuis et calages 100 % carton, fibres certifiées, sans plastique. | F9: Lot de 1 000 unités | G9: 410 | H9: Tous marchés | I9: Oui
A10: P009 | B10: SER-DM-600 | C10: Solution de sérialisation DataMatrix | D10: Équipements | E10: Module d'impression et de contrôle DataMatrix avec logiciel d'agrégation. | F10: Unité | G10: 68000 | H10: Pharmaceutique et santé | I10: Oui
A11: P010 | B11: ETQ-AUTO-400 | C11: Étiqueteuse automatique ETQ-400 | D11: Équipements | E11: Étiqueteuse automatique jusqu'à 200 produits par minute. | F11: Unité | G11: 42000 | H11: Tous marchés | I11: Oui
A12: P011 | B12: ENC-200 | C12: Encartonneuse automatique EC-200 | D12: Équipements | E12: Encartonneuse automatique jusqu'à 20 cartons par minute, changement de format rapide. | F12: Unité | G12: 125000 | H12: Tous marchés | I12: Oui
A13: P012 | B13: MNT-PREV-01 | C13: Contrat de maintenance préventive | D13: Services | E13: Deux visites préventives par an, assistance téléphonique et pièces d'usure. | F13: Contrat annuel | G13: 9600 | H13: Tous marchés | I13: Oui
... A15: P014 | B15: FOR-OPE-01 | C15: Formation opérateurs | D15: Services | E15: Formation sur site à la conduite et au réglage des équipements. | F15: Journée | G15: 1200 | H15: Tous marchés | I15: Oui

Sheet Entreprises
A1: ID entreprise | B1: Nom de l'entreprise | C1: Domaine du site web | D1: Site web | E1: Description de l'activité | F1: Secteur d'activité | G1: Sous-secteur | H1: Segment | I1: Tranche d'effectif | J1: Chiffre d'affaires annuel (tranche) | K1: Adresse | L1: Code postal | M1: Ville | N1: Région | O1: Pays | P1: Groupe / société mère | Q1: Cotée en bourse | R1: Code bourse (Yahoo Finance) | S1: ID propriétaire | T1: Propriétaire du compte | U1: Phase du cycle de vie | V1: Statut du compte | W1: Date de création | X1: Client depuis | Y1: Source d'origine | Z1: Potentiel annuel estimé (€) | AA1: CA 12 derniers mois (€) | AB1: Transactions ouvertes | AC1: Pipeline ouvert (€) | AD1: Tickets ouverts | AE1: Date de dernière activité | AF1: Prochain rendez-vous | AG1: Concurrent principal | AH1: Conditions de paiement | AI1: Contexte client | AJ1: Enjeux et projets en cours
A2: E001 | B2: Bonduelle | C2: bonduelle.com | D2: https://www.bonduelle.com | E2: Groupe agroalimentaire familial spécialisé dans les légumes transformés (conserve, surgelé, frais) ; marques Bonduelle et Cassegrain. | F2: Grande consommation | G2: Légumes transformés | H2: Grand compte | I2: 10 000 et plus | J2: 1 - 10 Md€ | K2: Rue Nicolas Appert | L2: 59650 | M2: Villeneuve-d'Ascq | N2: Hauts-de-France | O2: France | P2: Groupe Bonduelle | Q2: Oui | R2: BON.PA | S2: U002 | T2: =IFERROR(INDEX(Commerciaux!$D$2:$D$3000,MATCH(S2,Commerciaux!$A$2:$A$3000,0)),"") | U2: Client | V2: À surveiller | W2: 44481 | X2: 44621 | Y2: Salon professionnel | Z2: 420000 | AA2: =SUMIFS(Commandes!$K$2:$K$3000,Commandes!$D$2:$D$3000,A2,Commandes!$C$2:$C$3000,">"&(DateExport-365),Commandes!$C$2:$C$3000,"<="&DateExport) | AB2: =COUNTIFS(Transactions!$C$2:$C$3000,A2,Transactions!$N$2:$N$3000,"Ouverte") | AC2: =SUMIFS(Transactions!$L$2:$L$3000,Transactions!$C$2:$C$3000,A2,Transactions!$N$2:$N$3000,"Ouverte") | AD2: =COUNTIFS(Tickets!$C$2:$C$3000,A2,Tickets!$I$2:$I$3000,"<>Fermé") | AE2: =IF(COUNTIFS(Activités!$D$2:$D$3000,A2,Activités!$B$2:$B$3000,"<="&DateExport)=0,"",_xlfn.MAXIFS(Activités!$B$2:$B$3000,Activités!$D$2:$D$3000,A2,Activités!$B$2:$B$3000,"<="&DateExport)) | AF2: =IF(COUNTIFS('Rendez-vous'!$F$2:$F$3000,A2,'Rendez-vous'!$B$2:$B$3000,">="&DateExport)=0,"",_xlfn.MINIFS('Rendez-vous'!$B$2:$B$3000,'Rendez-vous'!$F$2:$F$3000,A2,'Rendez-vous'!$B$2:$B$3000,">="&DateExport)) | AG2: Labelis Group | AH2: 60 jours fin de mois | AI2: Client historique sur les étiquettes adhésives des gammes conserve. Les achats emballages sont pilotés depuis Villeneuve-d'Ascq, avec une validation qualité systématique de chaque nouvelle référence. Le groupe mène un plan de transformation centré sur la rentabilité et le désendettement : la direction achats a durci ses objectifs de réduction des coûts d'emballage. | AJ2: Renouvellement de l'accord-cadre étiquettes 2027 ; passage à des emballages mono-matériau sur deux gammes ; sécurisation des délais de livraison après le retard de septembre.
A3: E002 | B3: Lesaffre | C3: lesaffre.com | D3: https://www.lesaffre.com | E3: Groupe familial, leader mondial des levures et ferments pour la panification, la nutrition, la santé et les biotechnologies. | F3: Grande consommation | G3: Ingrédients et levures | H3: Grand compte | I3: 10 000 et plus | J3: 1 - 10 Md€ | K3: 137 rue Gabriel Péri | L3: 59700 | M3: Marcq-en-Barœul | N3: Hauts-de-France | O3: France | P3: Groupe Lesaffre | Q3: Non | S3: U002 | T3: =IFERROR(INDEX(Commerciaux!$D$2:$D$3000,MATCH(S3,Commerciaux!$A$2:$A$3000,0)),"") | U3: Client | V3: Actif | W3: 44684 | X3: 44880 | Y3: Prospection terrain | Z3: 380000 | AA3: =SUMIFS(Commandes!$K$2:$K$3000,Commandes!$D$2:$D$3000,A3,Commandes!$C$2:$C$3000,">"&(DateExport-365),Commandes!$C$2:$C$3000,"<="&DateExport) | AB3: =COUNTIFS(Transactions!$C$2:$C$3000,A3,Transactions!$N$2:$N$3000,"Ouverte") | AC3: =SUMIFS(Transactions!$L$2:$L$3000,Transactions!$C$2:$C$3000,A3,Transactions!$N$2:$N$3000,"Ouverte") | AD3: =COUNTIFS(Tickets!$C$2:$C$3000,A3,Tickets!$I$2:$I$3000,"<>Fermé") | AE3: =IF(COUNTIFS(Activités!$D$2:$D$3000,A3,Activités!$B$2:$B$3000,"<="&DateExport)=0,"",_xlfn.MAXIFS(Activités!$B$2:$B$3000,Activités!$D$2:$D$3000,A3,Activités!$B$2:$B$3000,"<="&DateExport)) | AF3: =IF(COUNTIFS('Rendez-vous'!$F$2:$F$3000,A3,'Rendez-vous'!$B$2:$B$3000,">="&DateExport)=0,"",_xlfn.MINIFS('Rendez-vous'!$B$2:$B$3000,'Rendez-vous'!$F$2:$F$3000,A3,'Rendez-vous'!$B$2:$B$3000,">="&DateExport)) | AG3: Emballor Industries | AH3: 45 jours fin de mois | AI3: Client sur les caisses carton et les étiquettes. Groupe familial en croissance qui investit dans de nouvelles capacités industrielles, en France comme à l'international. Relation construite avec le service achats ; l'arrivée d'un nouveau directeur industriel en 2026 ouvre la discussion sur l'automatisation des fins de ligne. | AJ3: Automatiser la mise en carton d'une ligne de levure sèche ; réduire la pénibilité au poste de palettisation ; décision d'investissement attendue avant la clôture budgétaire de fin d'année.
A4: E003 | B4: Guerbet | C4: guerbet.com | D4: https://www.guerbet.com | E4: Laboratoire pharmaceutique spécialiste des produits de contraste pour l'imagerie médicale et de la radiologie interventionnelle. | F4: Pharmaceutique et santé | G4: Imagerie médicale | H4: ETI | I4: 1 000 - 4 999 | J4: 100 M€ - 1 Md€ | K4: 15 rue des Vanesses | L4: 93420 | M4: Villepinte | N4: Île-de-France | O4: France | P4: Groupe Guerbet | Q4: Oui | R4: GBT.PA | S4: U002 | T4: =IFERROR(INDEX(Commerciaux!$D$2:$D$3000,MATCH(S4,Commerciaux!$A$2:$A$3000,0)),"") | U4: Client | V4: À risque | W4: 43871 | X4: 44075 | Y4: Recommandation | Z4: 260000 | AA4: =SUMIFS(Commandes!$K$2:$K$3000,Commandes!$D$2:$D$3000,A4,Commandes!$C$2:$C$3000,">"&(DateExport-365),Commandes!$C$2:$C$3000,"<="&DateExport) | AB4: =COUNTIFS(Transactions!$C$2:$C$3000,A4,Transactions!$N$2:$N$3000,"Ouverte") | AC4: =SUMIFS(Transactions!$L$2:$L$3000,Transactions!$C$2:$C$3000,A4,Transactions!$N$2:$N$3000,"Ouverte") | AD4: =COUNTIFS(Tickets!$C$2:$C$3000,A4,Tickets!$I$2:$I$3000,"<>Fermé") | AE4: =IF(COUNTIFS(Activités!$D$2:$D$3000,A4,Activités!$B$2:$B$3000,"<="&DateExport)=0,"",_xlfn.MAXIFS(Activités!$B$2:$B$3000,Activités!$D$2:$D$3000,A4,Activités!$B$2:$B$3000,"<="&DateExport)) | AF4: =IF(COUNTIFS('Rendez-vous'!$F$2:$F$3000,A4,'Rendez-vous'!$B$2:$B$3000,">="&DateExport)=0,"",_xlfn.MINIFS('Rendez-vous'!$B$2:$B$3000,'Rendez-vous'!$F$2:$F$3000,A4,'Rendez-vous'!$B$2:$B$3000,">="&DateExport)) | AG4: Kartéa Pharma Pack | AH4: 60 jours | AI4: Client sur les étuis et notices pharmaceutiques. Exigences qualité très élevées et audits fournisseurs annuels. Le groupe traverse une période difficile (plan de transformation, réduction des coûts, changement de direction générale) : les achats renégocient les contrats fournisseurs et la qualité est sous surveillance renforcée. Une non-conformité d'impression en juin 2026 a fragilisé la relation. | AJ4: Restaurer la confiance après l'incident qualité de juin ; réussir l'audit fournisseur de novembre ; projet de refonte des notices multilingues pour 2027.
A5: E004 | B5: Interparfums | C5: interparfums.fr | D5: https://www.interparfums.fr | E5: Créateur et distributeur de parfums sous licence et marques propres (Montblanc, Jimmy Choo, Coach, Lacoste, Lanvin). | F5: Grande consommation | G5: Parfums et cosmétiques | H5: ETI | I5: 250 - 999 | J5: 100 M€ - 1 Md€ | K5: 10 rue de Solférino | L5: 75007 | M5: Paris | N5: Île-de-France | O5: France | P5: Interparfums | Q5: Oui | R5: ITP.PA | S5: U002 | T5: =IFERROR(INDEX(Commerciaux!$D$2:$D$3000,MATCH(S5,Commerciaux!$A$2:$A$3000,0)),"") | U5: Client | V5: Actif | W5: 44942 | X5: 45082 | Y5: Salon professionnel | Z5: 210000 | AA5: =SUMIFS(Commandes!$K$2:$K$3000,Commandes!$D$2:$D$3000,A5,Commandes!$C$2:$C$3000,">"&(DateExport-365),Commandes!$C$2:$C$3000,"<="&DateExport) | AB5: =COUNTIFS(Transactions!$C$2:$C$3000,A5,Transactions!$N$2:$N$3000,"Ouverte") | AC5: =SUMIFS(Transactions!$L$2:$L$3000,Transactions!$C$2:$C$3000,A5,Transactions!$N$2:$N$3000,"Ouverte") | AD5: =COUNTIFS(Tickets!$C$2:$C$3000,A5,Tickets!$I$2:$I$3000,"<>Fermé") | AE5: =IF(COUNTIFS(Activités!$D$2:$D$3000,A5,Activités!$B$2:$B$3000,"<="&DateExport)=0,"",_xlfn.MAXIFS(Activités!$B$2:$B$3000,Activités!$D$2:$D$3000,A5,Activités!$B$2:$B$3000,"<="&DateExport)) | AF5: =IF(COUNTIFS('Rendez-vous'!$F$2:$F$3000,A5,'Rendez-vous'!$B$2:$B$3000,">="&DateExport)=0,"",_xlfn.MINIFS('Rendez-vous'!$B$2:$B$3000,'Rendez-vous'!$F$2:$F$3000,A5,'Rendez-vous'!$B$2:$B$3000,">="&DateExport)) | AG5: Cartonnages Vauclair | AH5: 60 jours | AI5: Client sur les coffrets rigides premium des éditions de fin d'année. Commandes très saisonnières, concentrées entre mai et septembre. | AJ5: Préparation des éditions limitées 2027 ; intérêt marqué pour des coffrets sans calage plastique.
A6: E005 | B6: Clarins | C6: clarins.com | D6: https://www.clarins.com | E6: Groupe familial de cosmétiques de soin et de maquillage. | F6: Grande consommation | G6: Cosmétiques de soin | H6: Grand compte | I6: 5 000 - 9 999 | J6: 1 - 10 Md€ | K6: 9 rue du Commandant Pilot | L6: 92200 | M6: Neuilly-sur-Seine | N6: Île-de-France | O6: France | P6: Groupe Clarins | Q6: Non | S6: U002 | T6: =IFERROR(INDEX(Commerciaux!$D$2:$D$3000,MATCH(S6,Commerciaux!$A$2:$A$3000,0)),"") | U6: Opportunité | V6: En développement | W6: 45981 | Y6: Site web | Z6: 300000 | AA6: =SUMIFS(Commandes!$K$2:$K$3000,Commandes!$D$2:$D$3000,A6,Commandes!$C$2:$C$3000,">"&(DateExport-365),Commandes!$C$2:$C$3000,"<="&DateExport) | AB6: =COUNTIFS(Transactions!$C$2:$C$3000,A6,Transactions!$N$2:$N$3000,"Ouverte") | AC6: =SUMIFS(Transactions!$L$2:$L$3000,Transactions!$C$2:$C$3000,A6,Transactions!$N$2:$N$3000,"Ouverte") | AD6: =COUNTIFS(Tickets!$C$2:$C$3000,A6,Tickets!$I$2:$I$3000,"<>Fermé") | AE6: =IF(COUNTIFS(Activités!$D$2:$D$3000,A6,Activités!$B$2:$B$3000,"<="&DateExport)=0,"",_xlfn.MAXIFS(Activités!$B$2:$B$3000,Activités!$D$2:$D$3000,A6,Activités!$B$2:$B$3000,"<="&DateExport)) | AF6: =IF(COUNTIFS('Rendez-vous'!$F$2:$F$3000,A6,'Rendez-vous'!$B$2:$B$3000,">="&DateExport)=0,"",_xlfn.MINIFS('Rendez-vous'!$B$2:$B$3000,'Rendez-vous'!$F$2:$F$3000,A6,'Rendez-vous'!$B$2:$B$3000,">="&DateExport)) | AG6: Cartonnages Vauclair | AH6: 60 jours | AI6: Demande entrante via le site web. Clarins cherche un second fournisseur d'étuis pour sécuriser ses approvisionnements. | AJ6: Référencement comme second fournisseur d'étuis ; exigences fortes sur l'éco-conception et la traçabilité des fibres.
A7: E006 | B7: Imerys | C7: imerys.com | D7: https://www.imerys.com | E7: Leader mondial des spécialités minérales pour l'industrie. | F7: Équipements et matériaux | G7: Minéraux industriels | H7: Grand compte | I7: 10 000 et plus | J7: 1 - 10 Md€ | K7: 43 quai de Grenelle | L7: 75015 | M7: Paris | N7: Île-de-France | O7: France | P7: Groupe Imerys | Q7: Oui | R7: NK.PA | S7: U002 | T7: =IFERROR(INDEX(Commerciaux!$D$2:$D$3000,MATCH(S7,Commerciaux!$A$2:$A$3000,0)),"") | U7: Prospect | V7: Nouveau | W7: 46262 | Y7: Prospection téléphonique | Z7: 150000 | AA7: =SUMIFS(Commandes!$K$2:$K$3000,Commandes!$D$2:$D$3000,A7,Commandes!$C$2:$C$3000,">"&(DateExport-365),Commandes!$C$2:$C$3000,"<="&DateExport) | AB7: =COUNTIFS(Transactions!$C$2:$C$3000,A7,Transactions!$N$2:$N$3000,"Ouverte") | AC7: =SUMIFS(Transactions!$L$2:$L$3000,Transactions!$C$2:$C$3000,A7,Transactions!$N$2:$N$3000,"Ouverte") | AD7: =COUNTIFS(Tickets!$C$2:$C$3000,A7,Tickets!$I$2:$I$3000,"<>Fermé") | AE7: =IF(COUNTIFS(Activités!$D$2:$D$3000,A7,Activités!$B$2:$B$3000,"<="&DateExport)=0,"",_xlfn.MAXIFS(Activités!$B$2:$B$3000,Activités!$D$2:$D$3000,A7,Activités!$B$2:$B$3000,"<="&DateExport)) | AF7: =IF(COUNTIFS('Rendez-vous'!$F$2:$F$3000,A7,'Rendez-vous'!$B$2:$B$3000,">="&DateExport)=0,"",_xlfn.MINIFS('Rendez-vous'!$B$2:$B$3000,'Rendez-vous'!$F$2:$F$3000,A7,'Rendez-vous'!$B$2:$B$3000,">="&DateExport)) | AH7: 60 jours | AI7: Prospect identifié par prospection téléphonique : besoin potentiel d'emballages de transport pour des minéraux en poudre. | AJ7: Qualifier le besoin, les volumes et le décideur achats.
A8: E007 | B8: Nexans | C8: nexans.com | D8: https://www.nexans.com | E8: Fabricant de câbles et de solutions de câblage pour l'électrification (réseaux, bâtiment, industrie). | F8: Équipements et matériaux | G8: Câbles et systèmes de câblage | H8: Grand compte | I8: 10 000 et plus | J8: 1 - 10 Md€ | K8: 4 allée de l'Arche | L8: 92400 | M8: Courbevoie | N8: Île-de-France | O8: France | P8: Groupe Nexans | Q8: Oui | R8: NEX.PA | S8: U002 | T8: =IFERROR(INDEX(Commerciaux!$D$2:$D$3000,MATCH(S8,Commerciaux!$A$2:$A$3000,0)),"") | U8: Client | V8: Actif | W8: 45027 | X8: 45201 | Y8: Recommandation | Z8: 180000 | AA8: =SUMIFS(Commandes!$K$2:$K$3000,Commandes!$D$2:$D$3000,A8,Commandes!$C$2:$C$3000,">"&(DateExport-365),Commandes!$C$2:$C$3000,"<="&DateExport) | AB8: =COUNTIFS(Transactions!$C$2:$C$3000,A8,Transactions!$N$2:$N$3000,"Ouverte") | AC8: =SUMIFS(Transactions!$L$2:$L$3000,Transactions!$C$2:$C$3000,A8,Transactions!$N$2:$N$3000,"Ouverte") | AD8: =COUNTIFS(Tickets!$C$2:$C$3000,A8,Tickets!$I$2:$I$3000,"<>Fermé") | AE8: =IF(COUNTIFS(Activités!$D$2:$D$3000,A8,Activités!$B$2:$B$3000,"<="&DateExport)=0,"",_xlfn.MAXIFS(Activités!$B$2:$B$3000,Activités!$D$2:$D$3000,A8,Activités!$B$2:$B$3000,"<="&DateExport)) | AF8: =IF(COUNTIFS('Rendez-vous'!$F$2:$F$3000,A8,'Rendez-vous'!$B$2:$B$3000,">="&DateExport)=0,"",_xlfn.MINIFS('Rendez-vous'!$B$2:$B$3000,'Rendez-vous'!$F$2:$F$3000,A8,'Rendez-vous'!$B$2:$B$3000,">="&DateExport)) | AG8: Emballor Industries | AH8: 60 jours | AI8: Client sur les caisses carton personnalisées et l'étiquetage logistique des accessoires de câblage. | AJ8: Réduction des emballages de transport ; harmonisation des étiquettes logistiques entre trois sites français.
A9: E008 | B9: Moët & Chandon | C9: moet.com | D9: https://www.moet.com | E9: Maison de champagne du groupe LVMH (Moët Hennessy). | F9: Vins et spiritueux | G9: Champagne | H9: Grand compte | I9: 1 000 - 4 999 | J9: Non publié (filiale) | K9: 20 avenue de Champagne | L9: 51200 | M9: Épernay | N9: Grand Est | O9: France | P9: LVMH (Moët Hennessy) | Q9: Oui (via le groupe) | R9: MC.PA | S9: U003 | T9: =IFERROR(INDEX(Commerciaux!$D$2:$D$3000,MATCH(S9,Commerciaux!$A$2:$A$3000,0)),"") | U9: Client | V9: Actif | W9: 43557 | X9: 43724 | Y9: Salon professionnel | Z9: 650000 | AA9: =SUMIFS(Commandes!$K$2:$K$3000,Commandes!$D$2:$D$3000,A9,Commandes!$C$2:$C$3000,">"&(DateExport-365),Commandes!$C$2:$C$3000,"<="&DateExport) | AB9: =COUNTIFS(Transactions!$C$2:$C$3000,A9,Transactions!$N$2:$N$3000,"Ouverte") | AC9: =SUMIFS(Transactions!$L$2:$L$3000,Transactions!$C$2:$C$3000,A9,Transactions!$N$2:$N$3000,"Ouverte") | AD9: =COUNTIFS(Tickets!$C$2:$C$3000,A9,Tickets!$I$2:$I$3000,"<>Fermé") | AE9: =IF(COUNTIFS(Activités!$D$2:$D$3000,A9,Activités!$B$2:$B$3000,"<="&DateExport)=0,"",_xlfn.MAXIFS(Activités!$B$2:$B$3000,Activités!$D$2:$D$3000,A9,Activités!$B$2:$B$3000,"<="&DateExport)) | AF9: =IF(COUNTIFS('Rendez-vous'!$F$2:$F$3000,A9,'Rendez-vous'!$B$2:$B$3000,">="&DateExport)=0,"",_xlfn.MINIFS('Rendez-vous'!$B$2:$B$3000,'Rendez-vous'!$F$2:$F$3000,A9,'Rendez-vous'!$B$2:$B$3000,">="&DateExport)) | AG9: Kartéa Luxe | AH9: 60 jours | AI9: Client stratégique sur les étuis luxe et les coffrets de fin d'année. Cycle de décision long impliquant marketing, achats et industriel. | AJ9: Production des coffrets de fin d'année 2026 ; consultation 2027 sur des étuis allégés ; exigences fortes de recyclabilité.
A10: E009 | B10: Laurent-Perrier | C10: laurent-perrier.com | D10: https://www.laurent-perrier.com | E10: Groupe familial de maisons de champagne (Laurent-Perrier, Salon, Delamotte, de Castellane). | F10: Vins et spiritueux | G10: Champagne | H10: ETI | I10: 250 - 999 | J10: 100 M€ - 1 Md€ | K10: 32 avenue de Champagne | L10: 51150 | M10: Tours-sur-Marne | N10: Grand Est | O10: France | P10: Groupe Laurent-Perrier | Q10: Oui | R10: LPE.PA | S10: U003 | T10: =IFERROR(INDEX(Commerciaux!$D$2:$D$3000,MATCH(S10,Commerciaux!$A$2:$A$3000,0)),"") | U10: Client | V10: Actif | W10: 44270 | X10: 44378 | Y10: Recommandation | Z10: 220000 | AA10: =SUMIFS(Commandes!$K$2:$K$3000,Commandes!$D$2:$D$3000,A10,Commandes!$C$2:$C$3000,">"&(DateExport-365),Commandes!$C$2:$C$3000,"<="&DateExport) | AB10: =COUNTIFS(Transactions!$C$2:$C$3000,A10,Transactions!$N$2:$N$3000,"Ouverte") | AC10: =SUMIFS(Transactions!$L$2:$L$3000,Transactions!$C$2:$C$3000,A10,Transactions!$N$2:$N$3000,"Ouverte") | AD10: =COUNTIFS(Tickets!$C$2:$C$3000,A10,Tickets!$I$2:$I$3000,"<>Fermé") | AE10: =IF(COUNTIFS(Activités!$D$2:$D$3000,A10,Activités!$B$2:$B$3000,"<="&DateExport)=0,"",_xlfn.MAXIFS(Activités!$B$2:$B$3000,Activités!$D$2:$D$3000,A10,Activités!$B$2:$B$3000,"<="&DateExport)) | AF10: =IF(COUNTIFS('Rendez-vous'!$F$2:$F$3000,A10,'Rendez-vous'!$B$2:$B$3000,">="&DateExport)=0,"",_xlfn.MINIFS('Rendez-vous'!$B$2:$B$3000,'Rendez-vous'!$F$2:$F$3000,A10,'Rendez-vous'!$B$2:$B$3000,">="&DateExport)) | AG10: Kartéa Luxe | AH10: 45 jours fin de mois | AI10: Client sur les étuis spiritueux et les caisses export. Interlocuteurs stables, relation de confiance. | AJ10: Renouvellement des étuis de la gamme rosé ; optimisation des caisses export.
A11: E010 | B11: Vranken-Pommery | C11: vrankenpommery.com | D11: https://www.vrankenpommery.com | E11: Groupe de vins et champagnes (Vranken, Pommery, Heidsieck & Co Monopole). | F11: Vins et spiritueux | G11: Champagne | H11: ETI | I11: 250 - 999 | J11: 100 M€ - 1 Md€ | K11: 5 place du Général Gouraud | L11: 51100 | M11: Reims | N11: Grand Est | O11: France | P11: Vranken-Pommery Monopole | Q11: Oui | R11: VRAP.PA | S11: U003 | T11: =IFERROR(INDEX(Commerciaux!$D$2:$D$3000,MATCH(S11,Commerciaux!$A$2:$A$3000,0)),"") | U11: Opportunité | V11: En développement | W11: 45908 | Y11: Salon professionnel | Z11: 240000 | AA11: =SUMIFS(Commandes!$K$2:$K$3000,Commandes!$D$2:$D$3000,A11,Commandes!$C$2:$C$3000,">"&(DateExport-365),Commandes!$C$2:$C$3000,"<="&DateExport) | AB11: =COUNTIFS(Transactions!$C$2:$C$3000,A11,Transactions!$N$2:$N$3000,"Ouverte") | AC11: =SUMIFS(Transactions!$L$2:$L$3000,Transactions!$C$2:$C$3000,A11,Transactions!$N$2:$N$3000,"Ouverte") | AD11: =COUNTIFS(Tickets!$C$2:$C$3000,A11,Tickets!$I$2:$I$3000,"<>Fermé") | AE11: =IF(COUNTIFS(Activités!$D$2:$D$3000,A11,Activités!$B$2:$B$3000,"<="&DateExport)=0,"",_xlfn.MAXIFS(Activités!$B$2:$B$3000,Activités!$D$2:$D$3000,A11,Activités!$B$2:$B$3000,"<="&DateExport)) | AF11: =IF(COUNTIFS('Rendez-vous'!$F$2:$F$3000,A11,'Rendez-vous'!$B$2:$B$3000,">="&DateExport)=0,"",_xlfn.MINIFS('Rendez-vous'!$B$2:$B$3000,'Rendez-vous'!$F$2:$F$3000,A11,'Rendez-vous'!$B$2:$B$3000,">="&DateExport)) | AG11: Kartéa Luxe | AH11: 60 jours | AI11: Opportunité ouverte après un salon professionnel : intérêt pour des coffrets premium et des étiquettes d'inviolabilité. | AJ11: Remplacement du fournisseur actuel de coffrets, jugé peu fiable sur les délais ; décision attendue en décembre.
A12: E011 | B12: Kronenbourg | C12: kronenbourg.com | D12: https://www.kronenbourg.com | E12: Premier brasseur français, filiale du groupe Carlsberg (Kronenbourg 1664, Grimbergen) ; principale brasserie à Obernai. | F12: Grande consommation | G12: Bière | H12: Grand compte | I12: 1 000 - 4 999 | J12: Non publié (filiale) | K12: 68 route d'Oberhausbergen | L12: 67000 | M12: Strasbourg | N12: Grand Est | O12: France | P12: Groupe Carlsberg | Q12: Oui (via le groupe) | R12: CARL-B.CO | S12: U003 | T12: =IFERROR(INDEX(Commerciaux!$D$2:$D$3000,MATCH(S12,Commerciaux!$A$2:$A$3000,0)),"") | U12: Client | V12: À risque | W12: 44004 | X12: 44207 | Y12: Prospection terrain | Z12: 320000 | AA12: =SUMIFS(Commandes!$K$2:$K$3000,Commandes!$D$2:$D$3000,A12,Commandes!$C$2:$C$3000,">"&(DateExport-365),Commandes!$C$2:$C$3000,"<="&DateExport) | AB12: =COUNTIFS(Transactions!$C$2:$C$3000,A12,Transactions!$N$2:$N$3000,"Ouverte") | AC12: =SUMIFS(Transactions!$L$2:$L$3000,Transactions!$C$2:$C$3000,A12,Transactions!$N$2:$N$3000,"Ouverte") | AD12: =COUNTIFS(Tickets!$C$2:$C$3000,A12,Tickets!$I$2:$I$3000,"<>Fermé") | AE12: =IF(COUNTIFS(Activités!$D$2:$D$3000,A12,Activités!$B$2:$B$3000,"<="&DateExport)=0,"",_xlfn.MAXIFS(Activités!$B$2:$B$3000,Activités!$D$2:$D$3000,A12,Activités!$B$2:$B$3000,"<="&DateExport)) | AF12: =IF(COUNTIFS('Rendez-vous'!$F$2:$F$3000,A12,'Rendez-vous'!$B$2:$B$3000,">="&DateExport)=0,"",_xlfn.MINIFS('Rendez-vous'!$B$2:$B$3000,'Rendez-vous'!$F$2:$F$3000,A12,'Rendez-vous'!$B$2:$B$3000,">="&DateExport)) | AG12: Emballor Industries | AH12: 60 jours | AI12: Client sur les caisses carton et les étiquettes promotionnelles. Les décisions d'achat se prennent au siège de Strasbourg ; la production est concentrée à la brasserie d'Obernai. Volume en baisse depuis début 2026 : une partie des caisses a été attribuée à un concurrent. | AJ12: Reconquérir le volume perdu sur les caisses ; valoriser le contrat de maintenance des étiqueteuses installées.
A13: E012 | B13: bioMérieux | C13: biomerieux.com | D13: https://www.biomerieux.com | E13: Acteur mondial du diagnostic in vitro (microbiologie, immunoessais, biologie moléculaire). | F13: Pharmaceutique et santé | G13: Diagnostic in vitro | H13: Grand compte | I13: 10 000 et plus | J13: 1 - 10 Md€ | K13: 376 chemin de l'Orme | L13: 69280 | M13: Marcy-l'Étoile | N13: Auvergne-Rhône-Alpes | O13: France | P13: bioMérieux | Q13: Oui | R13: BIM.PA | S13: U004 | T13: =IFERROR(INDEX(Commerciaux!$D$2:$D$3000,MATCH(S13,Commerciaux!$A$2:$A$3000,0)),"") | U13: Client | V13: Actif | W13: 44088 | X13: 44228 | Y13: Recommandation | Z13: 410000 | AA13: =SUMIFS(Commandes!$K$2:$K$3000,Commandes!$D$2:$D$3000,A13,Commandes!$C$2:$C$3000,">"&(DateExport-365),Commandes!$C$2:$C$3000,"<="&DateExport) | AB13: =COUNTIFS(Transactions!$C$2:$C$3000,A13,Transactions!$N$2:$N$3000,"Ouverte") | AC13: =SUMIFS(Transactions!$L$2:$L$3000,Transactions!$C$2:$C$3000,A13,Transactions!$N$2:$N$3000,"Ouverte") | AD13: =COUNTIFS(Tickets!$C$2:$C$3000,A13,Tickets!$I$2:$I$3000,"<>Fermé") | AE13: =IF(COUNTIFS(Activités!$D$2:$D$3000,A13,Activités!$B$2:$B$3000,"<="&DateExport)=0,"",_xlfn.MAXIFS(Activités!$B$2:$B$3000,Activités!$D$2:$D$3000,A13,Activités!$B$2:$B$3000,"<="&DateExport)) | AF13: =IF(COUNTIFS('Rendez-vous'!$F$2:$F$3000,A13,'Rendez-vous'!$B$2:$B$3000,">="&DateExport)=0,"",_xlfn.MINIFS('Rendez-vous'!$B$2:$B$3000,'Rendez-vous'!$F$2:$F$3000,A13,'Rendez-vous'!$B$2:$B$3000,">="&DateExport)) | AG13: Kartéa Pharma Pack | AH13: 60 jours | AI13: Client sur les étuis et étiquettes des kits de diagnostic. Forte exigence de traçabilité. | AJ13: Sérialisation des kits pour les marchés export ; évolution réglementaire de l'étiquetage.
A14: E013 | B14: Boiron | C14: boiron.com | D14: https://www.boiron.com | E14: Laboratoire pharmaceutique spécialiste de l'homéopathie et des médicaments sans ordonnance. | F14: Pharmaceutique et santé | G14: Homéopathie | H14: ETI | I14: 1 000 - 4 999 | J14: 100 M€ - 1 Md€ | K14: 2 avenue de l'Ouest Lyonnais | L14: 69510 | M14: Messimy | N14: Auvergne-Rhône-Alpes | O14: France | P14: Boiron | Q14: Oui | R14: BOI.PA | S14: U004 | T14: =IFERROR(INDEX(Commerciaux!$D$2:$D$3000,MATCH(S14,Commerciaux!$A$2:$A$3000,0)),"") | U14: Client | V14: Actif | W14: 43514 | X14: 43619 | Y14: Prospection terrain | Z14: 190000 | AA14: =SUMIFS(Commandes!$K$2:$K$3000,Commandes!$D$2:$D$3000,A14,Commandes!$C$2:$C$3000,">"&(DateExport-365),Commandes!$C$2:$C$3000,"<="&DateExport) | AB14: =COUNTIFS(Transactions!$C$2:$C$3000,A14,Transactions!$N$2:$N$3000,"Ouverte") | AC14: =SUMIFS(Transactions!$L$2:$L$3000,Transactions!$C$2:$C$3000,A14,Transactions!$N$2:$N$3000,"Ouverte") | AD14: =COUNTIFS(Tickets!$C$2:$C$3000,A14,Tickets!$I$2:$I$3000,"<>Fermé") | AE14: =IF(COUNTIFS(Activités!$D$2:$D$3000,A14,Activités!$B$2:$B$3000,"<="&DateExport)=0,"",_xlfn.MAXIFS(Activités!$B$2:$B$3000,Activités!$D$2:$D$3000,A14,Activités!$B$2:$B$3000,"<="&DateExport)) | AF14: =IF(COUNTIFS('Rendez-vous'!$F$2:$F$3000,A14,'Rendez-vous'!$B$2:$B$3000,">="&DateExport)=0,"",_xlfn.MINIFS('Rendez-vous'!$B$2:$B$3000,'Rendez-vous'!$F$2:$F$3000,A14,'Rendez-vous'!$B$2:$B$3000,">="&DateExport)) | AG14: Kartéa Pharma Pack | AH14: 60 jours | AI14: Client de longue date sur les étuis et notices, avec des volumes réguliers. | AJ14: Optimisation des coûts d'emballage ; passage à des étuis en carton recyclé.
A15: E014 | B15: SEB | C15: groupeseb.com | D15: https://www.groupeseb.com | E15: Leader mondial du petit équipement domestique (Tefal, Rowenta, Moulinex, Krups, Seb). | F15: Équipements et matériaux | G15: Petit électroménager | H15: Grand compte | I15: 10 000 et plus | J15: 1 - 10 Md€ | K15: 112 chemin du Moulin Carron | L15: 69130 | M15: Écully | N15: Auvergne-Rhône-Alpes | O15: France | P15: Groupe SEB | Q15: Oui | R15: SK.PA | S15: U004 | T15: =IFERROR(INDEX(Commerciaux!$D$2:$D$3000,MATCH(S15,Commerciaux!$A$2:$A$3000,0)),"") | U15: Client | V15: Actif | W15: 44221 | X15: 44326 | Y15: Salon professionnel | Z15: 520000 | AA15: =SUMIFS(Commandes!$K$2:$K$3000,Commandes!$D$2:$D$3000,A15,Commandes!$C$2:$C$3000,">"&(DateExport-365),Commandes!$C$2:$C$3000,"<="&DateExport) | AB15: =COUNTIFS(Transactions!$C$2:$C$3000,A15,Transactions!$N$2:$N$3000,"Ouverte") | AC15: =SUMIFS(Transactions!$L$2:$L$3000,Transactions!$C$2:$C$3000,A15,Transactions!$N$2:$N$3000,"Ouverte") | AD15: =COUNTIFS(Tickets!$C$2:$C$3000,A15,Tickets!$I$2:$I$3000,"<>Fermé") | AE15: =IF(COUNTIFS(Activités!$D$2:$D$3000,A15,Activités!$B$2:$B$3000,"<="&DateExport)=0,"",_xlfn.MAXIFS(Activités!$B$2:$B$3000,Activités!$D$2:$D$3000,A15,Activités!$B$2:$B$3000,"<="&DateExport)) | AF15: =IF(COUNTIFS('Rendez-vous'!$F$2:$F$3000,A15,'Rendez-vous'!$B$2:$B$3000,">="&DateExport)=0,"",_xlfn.MINIFS('Rendez-vous'!$B$2:$B$3000,'Rendez-vous'!$F$2:$F$3000,A15,'Rendez-vous'!$B$2:$B$3000,">="&DateExport)) | AG15: Emballor Industries | AH15: 60 jours | AI15: Client sur les caisses carton personnalisées et les emballages éco-conçus de plusieurs gammes. | AJ15: Suppression du polystyrène dans les calages ; harmonisation des emballages entre marques.
A16: E015 | B16: Vicat | C16: vicat.com | D16: https://www.vicat.com | E16: Groupe cimentier familial (ciment, béton prêt à l'emploi, granulats). | F16: Équipements et matériaux | G16: Ciment et matériaux de construction | H16: Grand compte | I16: 10 000 et plus | J16: 1 - 10 Md€ | K16: 4 rue Aristide Bergès | L16: 38080 | M16: L'Isle-d'Abeau | N16: Auvergne-Rhône-Alpes | O16: France | P16: Groupe Vicat | Q16: Oui | R16: VCT.PA | S16: U004 | T16: =IFERROR(INDEX(Commerciaux!$D$2:$D$3000,MATCH(S16,Commerciaux!$A$2:$A$3000,0)),"") | U16: Prospect | V16: Nouveau | W16: 46272 | Y16: Événement / webinaire | Z16: 120000 | AA16: =SUMIFS(Commandes!$K$2:$K$3000,Commandes!$D$2:$D$3000,A16,Commandes!$C$2:$C$3000,">"&(DateExport-365),Commandes!$C$2:$C$3000,"<="&DateExport) | AB16: =COUNTIFS(Transactions!$C$2:$C$3000,A16,Transactions!$N$2:$N$3000,"Ouverte") | AC16: =SUMIFS(Transactions!$L$2:$L$3000,Transactions!$C$2:$C$3000,A16,Transactions!$N$2:$N$3000,"Ouverte") | AD16: =COUNTIFS(Tickets!$C$2:$C$3000,A16,Tickets!$I$2:$I$3000,"<>Fermé") | AE16: =IF(COUNTIFS(Activités!$D$2:$D$3000,A16,Activités!$B$2:$B$3000,"<="&DateExport)=0,"",_xlfn.MAXIFS(Activités!$B$2:$B$3000,Activités!$D$2:$D$3000,A16,Activités!$B$2:$B$3000,"<="&DateExport)) | AF16: =IF(COUNTIFS('Rendez-vous'!$F$2:$F$3000,A16,'Rendez-vous'!$B$2:$B$3000,">="&DateExport)=0,"",_xlfn.MINIFS('Rendez-vous'!$B$2:$B$3000,'Rendez-vous'!$F$2:$F$3000,A16,'Rendez-vous'!$B$2:$B$3000,">="&DateExport)) | AH16: 60 jours | AI16: Prospect venu d'un webinaire sur l'étiquetage logistique : besoin potentiel d'étiquettes résistantes pour les sacs. | AJ16: Qualifier le besoin et identifier le décideur.
A17: E016 | B17: Virbac | C17: virbac.com | D17: https://www.virbac.com | E17: Laboratoire pharmaceutique dédié exclusivement à la santé animale. | F17: Pharmaceutique et santé | G17: Santé animale | H17: Grand compte | I17: 5 000 - 9 999 | J17: 1 - 10 Md€ | K17: 1ère avenue 2065 m LID | L17: 06510 | M17: Carros | N17: Provence-Alpes-Côte d'Azur | O17: France | P17: Virbac | Q17: Oui | R17: VIRP.PA | S17: U004 | T17: =IFERROR(INDEX(Commerciaux!$D$2:$D$3000,MATCH(S17,Commerciaux!$A$2:$A$3000,0)),"") | U17: Opportunité | V17: En développement | W17: 45994 | Y17: Recommandation | Z17: 280000 | AA17: =SUMIFS(Commandes!$K$2:$K$3000,Commandes!$D$2:$D$3000,A17,Commandes!$C$2:$C$3000,">"&(DateExport-365),Commandes!$C$2:$C$3000,"<="&DateExport) | AB17: =COUNTIFS(Transactions!$C$2:$C$3000,A17,Transactions!$N$2:$N$3000,"Ouverte") | AC17: =SUMIFS(Transactions!$L$2:$L$3000,Transactions!$C$2:$C$3000,A17,Transactions!$N$2:$N$3000,"Ouverte") | AD17: =COUNTIFS(Tickets!$C$2:$C$3000,A17,Tickets!$I$2:$I$3000,"<>Fermé") | AE17: =IF(COUNTIFS(Activités!$D$2:$D$3000,A17,Activités!$B$2:$B$3000,"<="&DateExport)=0,"",_xlfn.MAXIFS(Activités!$B$2:$B$3000,Activités!$D$2:$D$3000,A17,Activités!$B$2:$B$3000,"<="&DateExport)) | AF17: =IF(COUNTIFS('Rendez-vous'!$F$2:$F$3000,A17,'Rendez-vous'!$B$2:$B$3000,">="&DateExport)=0,"",_xlfn.MINIFS('Rendez-vous'!$B$2:$B$3000,'Rendez-vous'!$F$2:$F$3000,A17,'Rendez-vous'!$B$2:$B$3000,">="&DateExport)) | AG17: Kartéa Pharma Pack | AH17: 60 jours | AI17: Opportunité sur les étuis et la sérialisation d'une nouvelle ligne de produits vétérinaires. | AJ17: Choix d'un fournisseur de sérialisation pour une ligne prévue mi-2027 ; calendrier serré.
A18: E017 | B18: Rémy Cointreau | C18: remy-cointreau.com | D18: https://www.remy-cointreau.com | E18: Groupe de spiritueux premium (Rémy Martin, Louis XIII, Cointreau, The Botanist). | F18: Vins et spiritueux | G18: Cognac et liqueurs | H18: Grand compte | I18: 1 000 - 4 999 | J18: 100 M€ - 1 Md€ | K18: 20 rue de la Société Vinicole | L18: 16100 | M18: Cognac | N18: Nouvelle-Aquitaine | O18: France | P18: Rémy Cointreau | Q18: Oui | R18: RCO.PA | S18: U005 | T18: =IFERROR(INDEX(Commerciaux!$D$2:$D$3000,MATCH(S18,Commerciaux!$A$2:$A$3000,0)),"") | U18: Client | V18: Actif | W18: 44109 | X18: 44270 | Y18: Salon professionnel | Z18: 480000 | AA18: =SUMIFS(Commandes!$K$2:$K$3000,Commandes!$D$2:$D$3000,A18,Commandes!$C$2:$C$3000,">"&(DateExport-365),Commandes!$C$2:$C$3000,"<="&DateExport) | AB18: =COUNTIFS(Transactions!$C$2:$C$3000,A18,Transactions!$N$2:$N$3000,"Ouverte") | AC18: =SUMIFS(Transactions!$L$2:$L$3000,Transactions!$C$2:$C$3000,A18,Transactions!$N$2:$N$3000,"Ouverte") | AD18: =COUNTIFS(Tickets!$C$2:$C$3000,A18,Tickets!$I$2:$I$3000,"<>Fermé") | AE18: =IF(COUNTIFS(Activités!$D$2:$D$3000,A18,Activités!$B$2:$B$3000,"<="&DateExport)=0,"",_xlfn.MAXIFS(Activités!$B$2:$B$3000,Activités!$D$2:$D$3000,A18,Activités!$B$2:$B$3000,"<="&DateExport)) | AF18: =IF(COUNTIFS('Rendez-vous'!$F$2:$F$3000,A18,'Rendez-vous'!$B$2:$B$3000,">="&DateExport)=0,"",_xlfn.MINIFS('Rendez-vous'!$B$2:$B$3000,'Rendez-vous'!$F$2:$F$3000,A18,'Rendez-vous'!$B$2:$B$3000,">="&DateExport)) | AG18: Kartéa Luxe | AH18: 60 jours | AI18: Client sur les étuis spiritueux et les coffrets premium. Forte saisonnalité liée aux fêtes de fin d'année. | AJ18: Sécuriser les capacités pour la saison 2027 ; projet de coffret réutilisable pour la gamme premium.
A19: E018 | B19: Maison Ferrand | C19: maisonferrand.com | D19: https://www.maisonferrand.com | E19: Maison de spiritueux (Cognac Ferrand, rhums Planteray, gin Citadelle). | F19: Vins et spiritueux | G19: Cognac et rhums | H19: PME | I19: 50 - 249 | J19: Non publié | K19: Château de Bonbonnet | L19: 16130 | M19: Ars | N19: Nouvelle-Aquitaine | O19: France | P19: Maison Ferrand | Q19: Non | S19: U005 | T19: =IFERROR(INDEX(Commerciaux!$D$2:$D$3000,MATCH(S19,Commerciaux!$A$2:$A$3000,0)),"") | U19: Client | V19: Actif | W19: 44655 | X19: 44816 | Y19: Recommandation | Z19: 90000 | AA19: =SUMIFS(Commandes!$K$2:$K$3000,Commandes!$D$2:$D$3000,A19,Commandes!$C$2:$C$3000,">"&(DateExport-365),Commandes!$C$2:$C$3000,"<="&DateExport) | AB19: =COUNTIFS(Transactions!$C$2:$C$3000,A19,Transactions!$N$2:$N$3000,"Ouverte") | AC19: =SUMIFS(Transactions!$L$2:$L$3000,Transactions!$C$2:$C$3000,A19,Transactions!$N$2:$N$3000,"Ouverte") | AD19: =COUNTIFS(Tickets!$C$2:$C$3000,A19,Tickets!$I$2:$I$3000,"<>Fermé") | AE19: =IF(COUNTIFS(Activités!$D$2:$D$3000,A19,Activités!$B$2:$B$3000,"<="&DateExport)=0,"",_xlfn.MAXIFS(Activités!$B$2:$B$3000,Activités!$D$2:$D$3000,A19,Activités!$B$2:$B$3000,"<="&DateExport)) | AF19: =IF(COUNTIFS('Rendez-vous'!$F$2:$F$3000,A19,'Rendez-vous'!$B$2:$B$3000,">="&DateExport)=0,"",_xlfn.MINIFS('Rendez-vous'!$B$2:$B$3000,'Rendez-vous'!$F$2:$F$3000,A19,'Rendez-vous'!$B$2:$B$3000,">="&DateExport)) | AH19: 30 jours | AI19: Petit client très exigeant sur le design, commandes en petites séries. | AJ19: Étuis d'une édition limitée de fin d'année ; souplesse attendue sur les minimums de commande.
A20: E019 | B20: Pierre Fabre | C20: pierre-fabre.com | D20: https://www.pierre-fabre.com | E20: Groupe pharmaceutique et dermo-cosmétique (Avène, Ducray, Klorane, René Furterer). | F20: Pharmaceutique et santé | G20: Dermo-cosmétique et médicament | H20: Grand compte | I20: 5 000 - 9 999 | J20: 1 - 10 Md€ | K20: Parc industriel de la Chartreuse, 40 rue Albert Calmette | L20: 81100 | M20: Castres | N20: Occitanie | O20: France | P20: Groupe Pierre Fabre | Q20: Non | S20: U005 | T20: =IFERROR(INDEX(Commerciaux!$D$2:$D$3000,MATCH(S20,Commerciaux!$A$2:$A$3000,0)),"") | U20: Client | V20: À surveiller | W20: 44361 | X20: 44502 | Y20: Prospection terrain | Z20: 360000 | AA20: =SUMIFS(Commandes!$K$2:$K$3000,Commandes!$D$2:$D$3000,A20,Commandes!$C$2:$C$3000,">"&(DateExport-365),Commandes!$C$2:$C$3000,"<="&DateExport) | AB20: =COUNTIFS(Transactions!$C$2:$C$3000,A20,Transactions!$N$2:$N$3000,"Ouverte") | AC20: =SUMIFS(Transactions!$L$2:$L$3000,Transactions!$C$2:$C$3000,A20,Transactions!$N$2:$N$3000,"Ouverte") | AD20: =COUNTIFS(Tickets!$C$2:$C$3000,A20,Tickets!$I$2:$I$3000,"<>Fermé") | AE20: =IF(COUNTIFS(Activités!$D$2:$D$3000,A20,Activités!$B$2:$B$3000,"<="&DateExport)=0,"",_xlfn.MAXIFS(Activités!$B$2:$B$3000,Activités!$D$2:$D$3000,A20,Activités!$B$2:$B$3000,"<="&DateExport)) | AF20: =IF(COUNTIFS('Rendez-vous'!$F$2:$F$3000,A20,'Rendez-vous'!$B$2:$B$3000,">="&DateExport)=0,"",_xlfn.MINIFS('Rendez-vous'!$B$2:$B$3000,'Rendez-vous'!$F$2:$F$3000,A20,'Rendez-vous'!$B$2:$B$3000,">="&DateExport)) | AG20: Kartéa Pharma Pack | AH20: 60 jours | AI20: Client sur les étuis dermo-cosmétiques et les notices. Un ticket qualité est ouvert sur un défaut de pliage. | AJ20: Résoudre le défaut de pliage ; renouvellement du contrat étuis en janvier 2027.
A21: E020 | B21: Andros | C21: andros.fr | D21: https://www.andros.fr | E21: Groupe familial agroalimentaire (confitures, compotes, desserts, jus de fruits ; marques Andros et Bonne Maman). | F21: Grande consommation | G21: Fruits transformés et desserts | H21: Grand compte | I21: 5 000 - 9 999 | J21: 1 - 10 Md€ | K21: Zone industrielle | L21: 46130 | M21: Biars-sur-Cère | N21: Occitanie | O21: France | P21: Groupe Andros | Q21: Non | S21: U005 | T21: =IFERROR(INDEX(Commerciaux!$D$2:$D$3000,MATCH(S21,Commerciaux!$A$2:$A$3000,0)),"") | U21: Opportunité | V21: En développement | W21: 46083 | Y21: Salon professionnel | Z21: 260000 | AA21: =SUMIFS(Commandes!$K$2:$K$3000,Commandes!$D$2:$D$3000,A21,Commandes!$C$2:$C$3000,">"&(DateExport-365),Commandes!$C$2:$C$3000,"<="&DateExport) | AB21: =COUNTIFS(Transactions!$C$2:$C$3000,A21,Transactions!$N$2:$N$3000,"Ouverte") | AC21: =SUMIFS(Transactions!$L$2:$L$3000,Transactions!$C$2:$C$3000,A21,Transactions!$N$2:$N$3000,"Ouverte") | AD21: =COUNTIFS(Tickets!$C$2:$C$3000,A21,Tickets!$I$2:$I$3000,"<>Fermé") | AE21: =IF(COUNTIFS(Activités!$D$2:$D$3000,A21,Activités!$B$2:$B$3000,"<="&DateExport)=0,"",_xlfn.MAXIFS(Activités!$B$2:$B$3000,Activités!$D$2:$D$3000,A21,Activités!$B$2:$B$3000,"<="&DateExport)) | AF21: =IF(COUNTIFS('Rendez-vous'!$F$2:$F$3000,A21,'Rendez-vous'!$B$2:$B$3000,">="&DateExport)=0,"",_xlfn.MINIFS('Rendez-vous'!$B$2:$B$3000,'Rendez-vous'!$F$2:$F$3000,A21,'Rendez-vous'!$B$2:$B$3000,">="&DateExport)) | AG21: Emballor Industries | AH21: 60 jours | AI21: Opportunité sur les caisses carton et l'étiquetage d'une nouvelle gamme lancée en 2027. | AJ21: Trouver un fournisseur capable de suivre une montée en volume rapide, avec de la souplesse la première année.
A22: E021 | B22: Volterra | C22: volterra.example | D22: https://www.volterra.example | E22: Spécialiste mondial des infrastructures électriques et numériques du bâtiment. | F22: Équipements et matériaux | G22: Matériel électrique | H22: Grand compte | I22: 10 000 et plus | J22: 1 - 10 Md€ | K22: 12 rue des Isolants | L22: 86000 | M22: Poitiers | N22: Nouvelle-Aquitaine | O22: France | P22: Groupe Volterra | Q22: Oui | S22: U005 | T22: =IFERROR(INDEX(Commerciaux!$D$2:$D$3000,MATCH(S22,Commerciaux!$A$2:$A$3000,0)),"") | U22: Client | V22: Actif | W22: 43850 | X22: 43990 | Y22: Recommandation | Z22: 450000 | AA22: =SUMIFS(Commandes!$K$2:$K$3000,Commandes!$D$2:$D$3000,A22,Commandes!$C$2:$C$3000,">"&(DateExport-365),Commandes!$C$2:$C$3000,"<="&DateExport) | AB22: =COUNTIFS(Transactions!$C$2:$C$3000,A22,Transactions!$N$2:$N$3000,"Ouverte") | AC22: =SUMIFS(Transactions!$L$2:$L$3000,Transactions!$C$2:$C$3000,A22,Transactions!$N$2:$N$3000,"Ouverte") | AD22: =COUNTIFS(Tickets!$C$2:$C$3000,A22,Tickets!$I$2:$I$3000,"<>Fermé") | AE22: =IF(COUNTIFS(Activités!$D$2:$D$3000,A22,Activités!$B$2:$B$3000,"<="&DateExport)=0,"",_xlfn.MAXIFS(Activités!$B$2:$B$3000,Activités!$D$2:$D$3000,A22,Activités!$B$2:$B$3000,"<="&DateExport)) | AF22: =IF(COUNTIFS('Rendez-vous'!$F$2:$F$3000,A22,'Rendez-vous'!$B$2:$B$3000,">="&DateExport)=0,"",_xlfn.MINIFS('Rendez-vous'!$B$2:$B$3000,'Rendez-vous'!$F$2:$F$3000,A22,'Rendez-vous'!$B$2:$B$3000,">="&DateExport)) | AG22: Emballor Industries | AH22: 60 jours | AI22: Client sur les caisses carton et les emballages éco-conçus de l'appareillage électrique. Une étiqueteuse ETQ-400 est installée sur le site de Poitiers. | AJ22: Réduction du plastique dans les emballages de vente ; déploiement sur deux usines supplémentaires.
A23: E022 | B23: Sanofi | C23: sanofi.com | D23: https://www.sanofi.com | E23: Groupe biopharmaceutique mondial (médicaments de spécialité, vaccins, médicaments généraux). | F23: Pharmaceutique et santé | G23: Médicaments de prescription et vaccins | H23: Grand compte | I23: 10 000 et plus | J23: Plus de 10 Md€ | K23: 46 avenue de la Grande Armée | L23: 75017 | M23: Paris | N23: Île-de-France | O23: France | P23: Groupe Sanofi | Q23: Oui | R23: SAN.PA | S23: U006 | T23: =IFERROR(INDEX(Commerciaux!$D$2:$D$3000,MATCH(S23,Commerciaux!$A$2:$A$3000,0)),"") | U23: Client | V23: Actif | W23: 43437 | X23: 43605 | Y23: Prospection terrain | Z23: 1200000 | AA23: =SUMIFS(Commandes!$K$2:$K$3000,Commandes!$D$2:$D$3000,A23,Commandes!$C$2:$C$3000,">"&(DateExport-365),Commandes!$C$2:$C$3000,"<="&DateExport) | AB23: =COUNTIFS(Transactions!$C$2:$C$3000,A23,Transactions!$N$2:$N$3000,"Ouverte") | AC23: =SUMIFS(Transactions!$L$2:$L$3000,Transactions!$C$2:$C$3000,A23,Transactions!$N$2:$N$3000,"Ouverte") | AD23: =COUNTIFS(Tickets!$C$2:$C$3000,A23,Tickets!$I$2:$I$3000,"<>Fermé") | AE23: =IF(COUNTIFS(Activités!$D$2:$D$3000,A23,Activités!$B$2:$B$3000,"<="&DateExport)=0,"",_xlfn.MAXIFS(Activités!$B$2:$B$3000,Activités!$D$2:$D$3000,A23,Activités!$B$2:$B$3000,"<="&DateExport)) | AF23: =IF(COUNTIFS('Rendez-vous'!$F$2:$F$3000,A23,'Rendez-vous'!$B$2:$B$3000,">="&DateExport)=0,"",_xlfn.MINIFS('Rendez-vous'!$B$2:$B$3000,'Rendez-vous'!$F$2:$F$3000,A23,'Rendez-vous'!$B$2:$B$3000,">="&DateExport)) | AG23: Kartéa Pharma Pack | AH23: 60 jours | AI23: Grand compte stratégique. Accord-cadre national sur les étuis et notices, décliné par site de production. Plusieurs interlocuteurs achats et industriels. | AJ23: Renouvellement de l'accord-cadre en 2027 ; déploiement de la sérialisation sur un site supplémentaire.
A24: E023 | B24: Ipsen | C24: ipsen.com | D24: https://www.ipsen.com | E24: Groupe biopharmaceutique spécialisé en oncologie, maladies rares et neurosciences. | F24: Pharmaceutique et santé | G24: Médicaments de spécialité | H24: Grand compte | I24: 5 000 - 9 999 | J24: 1 - 10 Md€ | K24: 65 quai Georges Gorse | L24: 92100 | M24: Boulogne-Billancourt | N24: Île-de-France | O24: France | P24: Ipsen | Q24: Oui | R24: IPN.PA | S24: U006 | T24: =IFERROR(INDEX(Commerciaux!$D$2:$D$3000,MATCH(S24,Commerciaux!$A$2:$A$3000,0)),"") | U24: Client | V24: Actif | W24: 43899 | X24: 44116 | Y24: Recommandation | Z24: 380000 | AA24: =SUMIFS(Commandes!$K$2:$K$3000,Commandes!$D$2:$D$3000,A24,Commandes!$C$2:$C$3000,">"&(DateExport-365),Commandes!$C$2:$C$3000,"<="&DateExport) | AB24: =COUNTIFS(Transactions!$C$2:$C$3000,A24,Transactions!$N$2:$N$3000,"Ouverte") | AC24: =SUMIFS(Transactions!$L$2:$L$3000,Transactions!$C$2:$C$3000,A24,Transactions!$N$2:$N$3000,"Ouverte") | AD24: =COUNTIFS(Tickets!$C$2:$C$3000,A24,Tickets!$I$2:$I$3000,"<>Fermé") | AE24: =IF(COUNTIFS(Activités!$D$2:$D$3000,A24,Activités!$B$2:$B$3000,"<="&DateExport)=0,"",_xlfn.MAXIFS(Activités!$B$2:$B$3000,Activités!$D$2:$D$3000,A24,Activités!$B$2:$B$3000,"<="&DateExport)) | AF24: =IF(COUNTIFS('Rendez-vous'!$F$2:$F$3000,A24,'Rendez-vous'!$B$2:$B$3000,">="&DateExport)=0,"",_xlfn.MINIFS('Rendez-vous'!$B$2:$B$3000,'Rendez-vous'!$F$2:$F$3000,A24,'Rendez-vous'!$B$2:$B$3000,">="&DateExport)) | AG24: Kartéa Pharma Pack | AH24: 60 jours | AI24: Client sur les étuis et étiquettes de médicaments de spécialité. | AJ24: Généralisation des étiquettes d'inviolabilité sur toute la gamme ; clause de révision annuelle des prix demandée.
A25: E024 | B25: Servier | C25: servier.com | D25: https://www.servier.com | E25: Groupe pharmaceutique indépendant gouverné par une fondation, spécialisé notamment en oncologie et cardiologie. | F25: Pharmaceutique et santé | G25: Médicaments de prescription | H25: Grand compte | I25: 10 000 et plus | J25: 1 - 10 Md€ | K25: 50 rue Carnot | L25: 92150 | M25: Suresnes | N25: Île-de-France | O25: France | P25: Groupe Servier | Q25: Non | S25: U006 | T25: =IFERROR(INDEX(Commerciaux!$D$2:$D$3000,MATCH(S25,Commerciaux!$A$2:$A$3000,0)),"") | U25: Opportunité | V25: En développement | W25: 45944 | Y25: Événement / webinaire | Z25: 500000 | AA25: =SUMIFS(Commandes!$K$2:$K$3000,Commandes!$D$2:$D$3000,A25,Commandes!$C$2:$C$3000,">"&(DateExport-365),Commandes!$C$2:$C$3000,"<="&DateExport) | AB25: =COUNTIFS(Transactions!$C$2:$C$3000,A25,Transactions!$N$2:$N$3000,"Ouverte") | AC25: =SUMIFS(Transactions!$L$2:$L$3000,Transactions!$C$2:$C$3000,A25,Transactions!$N$2:$N$3000,"Ouverte") | AD25: =COUNTIFS(Tickets!$C$2:$C$3000,A25,Tickets!$I$2:$I$3000,"<>Fermé") | AE25: =IF(COUNTIFS(Activités!$D$2:$D$3000,A25,Activités!$B$2:$B$3000,"<="&DateExport)=0,"",_xlfn.MAXIFS(Activités!$B$2:$B$3000,Activités!$D$2:$D$3000,A25,Activités!$B$2:$B$3000,"<="&DateExport)) | AF25: =IF(COUNTIFS('Rendez-vous'!$F$2:$F$3000,A25,'Rendez-vous'!$B$2:$B$3000,">="&DateExport)=0,"",_xlfn.MINIFS('Rendez-vous'!$B$2:$B$3000,'Rendez-vous'!$F$2:$F$3000,A25,'Rendez-vous'!$B$2:$B$3000,">="&DateExport)) | AG25: Kartéa Pharma Pack | AH25: 60 jours | AI25: Opportunité de référencement sur les notices et étuis d'un site de production. | AJ25: Appel d'offres en cours, trois fournisseurs retenus ; décision attendue au premier trimestre 2027.
A26: E025 | B26: Pernod Ricard | C26: pernod-ricard.com | D26: https://www.pernod-ricard.com | E26: Numéro deux mondial des vins et spiritueux (Absolut, Jameson, Ricard, Martell, Chivas Regal). | F26: Vins et spiritueux | G26: Spiritueux | H26: Grand compte | I26: 10 000 et plus | J26: 1 - 10 Md€ | K26: 5 cours Paul Ricard | L26: 75008 | M26: Paris | N26: Île-de-France | O26: France | P26: Groupe Pernod Ricard | Q26: Oui | R26: RI.PA | S26: U007 | T26: =IFERROR(INDEX(Commerciaux!$D$2:$D$3000,MATCH(S26,Commerciaux!$A$2:$A$3000,0)),"") | U26: Client | V26: Actif | W26: 43479 | X26: 43647 | Y26: Salon professionnel | Z26: 950000 | AA26: =SUMIFS(Commandes!$K$2:$K$3000,Commandes!$D$2:$D$3000,A26,Commandes!$C$2:$C$3000,">"&(DateExport-365),Commandes!$C$2:$C$3000,"<="&DateExport) | AB26: =COUNTIFS(Transactions!$C$2:$C$3000,A26,Transactions!$N$2:$N$3000,"Ouverte") | AC26: =SUMIFS(Transactions!$L$2:$L$3000,Transactions!$C$2:$C$3000,A26,Transactions!$N$2:$N$3000,"Ouverte") | AD26: =COUNTIFS(Tickets!$C$2:$C$3000,A26,Tickets!$I$2:$I$3000,"<>Fermé") | AE26: =IF(COUNTIFS(Activités!$D$2:$D$3000,A26,Activités!$B$2:$B$3000,"<="&DateExport)=0,"",_xlfn.MAXIFS(Activités!$B$2:$B$3000,Activités!$D$2:$D$3000,A26,Activités!$B$2:$B$3000,"<="&DateExport)) | AF26: =IF(COUNTIFS('Rendez-vous'!$F$2:$F$3000,A26,'Rendez-vous'!$B$2:$B$3000,">="&DateExport)=0,"",_xlfn.MINIFS('Rendez-vous'!$B$2:$B$3000,'Rendez-vous'!$F$2:$F$3000,A26,'Rendez-vous'!$B$2:$B$3000,">="&DateExport)) | AG26: Kartéa Luxe | AH26: 60 jours | AI26: Grand compte sur les étuis et coffrets de plusieurs marques. Achats centralisés, déclinés par filiale. | AJ26: Programme d'éco-conception des coffrets ; révision du panel fournisseurs en 2027.
